I'm sorry, but an uncaught exception occurred.

While running game code:
  File "game/pia/chapter2pia.rpy", line 250, in script
    show fio_side at left with dissolve
Exception: Sayer 'pio' is not defined.

-- Full Traceback ------------------------------------------------------------

Full traceback:
  File "game/pia/chapter2pia.rpy", line 250, in script
    show fio_side at left with dissolve
  File "D:\Alief\Project\Fanbase\Games\renpy-8.2.1-sdk\renpy\ast.py", line 2557, in execute
    Say.execute(self)
  File "D:\Alief\Project\Fanbase\Games\renpy-8.2.1-sdk\renpy\ast.py", line 575, in execute
    who = eval_who(self.who, self.who_fast)
  File "D:\Alief\Project\Fanbase\Games\renpy-8.2.1-sdk\renpy\ast.py", line 464, in eval_who
    raise Exception("Sayer '%s' is not defined." % who)
Exception: Sayer 'pio' is not defined.

Windows-10-10.0.22631 AMD64
Ren'Py 8.2.1.24030407
WGV:Dreamcatcher 
Fri Jun 14 15:04:21 2024
